Workbook

Sheet 30_04_20
A1: 201
D2: Liquid Assests | G2: Read This | J2: Tied Assests
D3: Prod | E3: Where | F3: Who | G3: 43951 | H3: 43920 | J3: Prod | K3: Where | L3: Who | M3: Amount | Q3: At Risk | R3: Not a Risk - Cash
B4: =488+743 -> 1231 | D4: ISA | E4: Ford | F4: JG | G4: 30657 | H4: 28871 | J4: Jenny | M4: 0 | Q4: =G24-R4 -> 266541 | R4: =SUM(G11:G15) -> 236100 | T4: 130 | V4: 102.8 | W4: Share Price
B5: =504+803 -> 1307 | D5: ISA | E5: Ford | F5: MG | G5: 30657 | H5: 28871 | J5: Faye | M5: 22000 | P5: this is 17k + 5K | T5: 71 | V5: 1.125 | W5: Exchange | AE5: NSI | AF5: 100000
D6: FundSmith | G6: 7491 | H6: 6902 | J6: Nik | M6: 5000 | N6: 155K | P6: Med | Q6: =G4+G5+G16+G17+G18 -> 246723 | T6: =T4-T5 -> 59 | AE6: Share | AF6: 85000
C7: * | D7: Hargrevaes Lansdown | G7: 1091 | H7: 887 | P7: High | Q7: =SUM(G6:G10) -> 19818
C8: * | D8: Intractive Investor | G8: 10718 | H8: 9320
C9: * | D9: Bakkovor Now III | G9: 367 | H9: 552
C10: * | D10: Coinbase | G10: 151 | H10: 100 | J10: lister st | M10: 0
D11: Current account - Inv, Currt and Holid | E11: Nat West Invest/Holiday - Not EX, Not Prop, Not Current below 4K | G11: 75000 | H11: =66000+8000 -> 74000 | J11: Phil | M11: 1500 | R11: =14514*2 -> 29028 | AE11: Invest | AF11: 40000
D12: Premium Bonds | E12: Post Office | F12: JG | G12: 50000 | H12: 50000 | J12: House | K12: 2bed | M12: 37000 | AF12: =SUM(AF5:AF11) -> 225000
D13: Premium Bonds | E13: Post Office | F13: BH | G13: 11100 | H13: 10950
D14: Premium Bonds | E14: Post Office | F14: FG | G14: 50000 | H14: 50000 | Q14: 81287
A15: Q3 | B15: Q2 | C15: 2018 | D15: Premium Bonds | E15: Post Office | F15: MG | G15: 50000 | H15: 50000 | J15: House | K15: 3bed | M15: 35000 | Q15: =G4*2 -> 61314
A16: 766 | B16: 766 | C16: 523 | D16: EDSP | E16: Computershare | F16: MG | G16: 72611 | H16: 69937 | J16: Total | M16: =SUM(M4:M15) -> 100500 | N16: 73707 | Q16: =Q14-Q15 -> 19973 | X16: =SUM(A16:A18) -> 1867 | Y16: =X16*V4 -> 191927.6
A17: 504 | B17: 504 | D17: Trading Acocunt | E17: III ( both JG and MG) | F17: MGJG | G17: =23291*2 -> 46582 | H17: =22512+23423 -> 45935
A18: 597 | B18: 555 | C18: 684 | D18: OWN SAP | F18: MG | G18: 66216 | H18: 62398
A19: 2011 | C19: 99 | D19: SAP Shares | E19: 1 free | F19: MG | H19: 33 | J19: SAP Shares | K19: 1 free | N19: 42156 | P19: 37666 | W19: =388*70/1.43 -> 18993.007
A20: 2012 | C20: 96 | D20: SAP Shares | E20: 5 p 3y 3g | F20: MG | H20: 160 | J20: SAP Shares | K20: 5 p 3y 3g | N20: 41791 | P20: 35143
A21: 2013 | C21: 87 | D21: SAP Shares | E21: B3K3G1 | F21: MG | H21: 29 | J21: SAP Shares | K21: B3K3G1 | N21: 42583
M22: =SUM(M19:M21) -> 0
D24: Total | G24: =SUM(G4:G18) -> 502641 | H24: =SUM(H4:H18) -> 488723 | I24: 504894 | K24: =G26-H24 -> 13918 | M24: =M16+M22 -> 100500 | Z24: 1155
Q25: 900 | Z25: 80.13
D26: Potential Balance | G26: =G24 -> 502641 | H26: 493260 | K26: 7773 | AA26: =Z25*Z24 -> 92550.15
D27: Not so liquid | N27: Actual | O27: 31st Dec | P27: 31st Dec | Q27: 31st Dec | R27: 31st Dec | S27: 31st Dec | T27: 31st Dec | Z27: 1.5 | AA27: =AA26/Z27 -> 61700.1
D28: Aston | E28: Sold | G28: 0 | O28: 2015 | P28: 2016 | Q28: 2017 | R28: 2018 | S28: 2019 | T28: 2020 | U28: =T28+1 -> 2021
D29: Golf R | G29: 15000 | N29: Value | O29: 164433.05 | P29: 248589.4 | Q29: 314989.19 | R29: 335945 | S29: 336562 | T29: 374989.19
D30: Motor Bike | G30: 2000 | O30: 0 | P30: 0 | S30: 30000 | T30: 7000
G31: =SUM(G28:G30) -> 17000 | N31: Santandar | O31: 29028
N32: Total | O32: 193461.05 | P32: 248589.4 | Q32: 314989.19 | R32: 335945 | S32: 374989.19 | T32: 381989.19
D33: Less CC Debit | G33: 1600 | P33: 55128.35 | Q33: 66399.786 | R33: =R32-Q32 -> 20955.812
D35: Sub Total | G35: =G26+G31-G33 -> 518041 | N35: Q1 | P35: 282432.89 | Q35: 33843.485 | R35: 8687 | S35: 120736 | Z35: phil | AA35: 1500
N36: Q2 | P36: 294892.7 | Q36: 12459.809 | R36: 5697 | S36: 43735
D37: Tied Assetts | G37: =M24 -> 100500 | N37: Q3 | P37: 310690.69 | Q37: 15797.999 | R37: 37050 | S37: -7000
N38: Q4 | P38: 314989.19 | Q38: 4298.4936 | R38: -31361 | S38: 11634
D39: House | G39: 360000 | Q39: 66399.786 | R39: =SUM(R35:R38) -> 20073 | S39: =SUM(S35:S38) -> 169105
D40: less mortgage | G40: =G39 -> 360000
N41: Budget | O41: 31st Dec | P41: 31st Dec | Q41: 31st Dec | R41: 31st Dec | S41: 31st Dec | T41: 31st Dec | Z41: RN Pension
D42: Nett Worth | G42: =G40+G37+G35 -> 978541 | O42: 2015 | P42: 2016 | Q42: 2017 | R42: 2018 | S42: 2019 | T42: 2020 | Z42: Nissan | AA42: GSR Capital
...

Sheet 29_05_20
A1: 201
D2: Liquid Assests | G2: Read This | J2: Tied Assests
D3: Prod | E3: Where | F3: Who | G3: 43980 | H3: 43951 | J3: Prod | K3: Where | L3: Who | M3: Amount | Q3: At Risk | R3: Not a Risk - Cash
B4: =488+743 -> 1231 | D4: ISA | E4: Ford | F4: JG | G4: 52605 | H4: 30657 | J4: Jenny | M4: 0 | Q4: =G24-R4 -> 329648 | R4: =SUM(G11:G15) -> 199900 | T4: 130 | V4: 102.8 | W4: Share Price
B5: =504+803 -> 1307 | D5: ISA | E5: Ford | F5: MG | G5: 52605 | H5: 30657 | J5: Faye | M5: 22000 | P5: this is 17k + 5K | T5: 71 | V5: 1.125 | W5: Exchange | AE5: NSI | AF5: 100000
D6: FundSmith | G6: 8024 | H6: 7491 | J6: Nik | M6: 5000 | N6: 155K | P6: Med | Q6: =G4+G5+G16+G17+G18 -> 308286 | T6: =T4-T5 -> 59 | AE6: Share | AF6: 85000
C7: * | D7: Hargrevaes Lansdown | G7: 1156 | H7: 1091 | P7: High | Q7: =SUM(G6:G10) -> 21362
C8: * | D8: Intractive Investor | G8: 11606 | H8: 10718
C9: * | D9: Bakkovor Now III | G9: 410 | H9: 367
C10: * | D10: Coinbase | G10: 166 | H10: 151 | J10: lister st | M10: 0
D11: Current account - Inv, Currt and Holid | E11: Nat West Invest/Holiday - Not EX, Not Prop, Not Current below 4K | G11: 38800 | H11: 75000 | J11: Phil | M11: 1500 | R11: =14514*2 -> 29028 | AE11: Invest | AF11: 40000
D12: Premium Bonds | E12: Post Office | F12: JG | G12: 50000 | H12: 50000 | J12: House | K12: 2bed | M12: 37000 | AF12: =SUM(AF5:AF11) -> 225000
D13: Premium Bonds | E13: Post Office | F13: BH | G13: 11100 | H13: 11100
D14: Premium Bonds | E14: Post Office | F14: FG | G14: 50000 | H14: 50000 | Q14: 81287
A15: Q3 | B15: Q2 | C15: 2018 | D15: Premium Bonds | E15: Post Office | F15: MG | G15: 50000 | H15: 50000 | J15: House | K15: 3bed | M15: 35000 | Q15: =G4*2 -> 105210
A16: 766 | B16: 766 | C16: 523 | D16: EDSP | E16: Computershare | F16: MG | G16: 78218 | H16: 72611 | J16: Total | M16: =SUM(M4:M15) -> 100500 | N16: 73707 | Q16: =Q14-Q15 -> -23923 | X16: =SUM(A16:A18) -> 1867 | Y16: =X16*V4 -> 191927.6
A17: 504 | B17: 504 | D17: Trading Acocunt | E17: III ( both JG and MG) | F17: MGJG | G17: =25420+26482 -> 51902 | H17: =23291*2 -> 46582
A18: 597 | B18: 555 | C18: 715 | D18: OWN SAP | F18: MG | G18: 72956 | H18: 66216
A19: 2011 | C19: 99 | D19: SAP Shares | E19: 1 free | F19: MG | H19: 33 | J19: SAP Shares | K19: 1 free | N19: 42156 | P19: 37666 | W19: =388*70/1.43 -> 18993.007
A20: 2012 | C20: 96 | D20: SAP Shares | E20: 5 p 3y 3g | F20: MG | H20: 160 | J20: SAP Shares | K20: 5 p 3y 3g | N20: 41791 | P20: 35143
A21: 2013 | C21: 87 | D21: SAP Shares | E21: B3K3G1 | F21: MG | H21: 29 | J21: SAP Shares | K21: B3K3G1 | N21: 42583
M22: =SUM(M19:M21) -> 0
D24: Total | G24: =SUM(G4:G18) -> 529548 | H24: =SUM(H4:H18) -> 502641 | I24: 504894 | K24: =G26-H24 -> 26907 | M24: =M16+M22 -> 100500 | Z24: 1155
Q25: 900 | Z25: 80.13
D26: Potential Balance | G26: =G24 -> 529548 | H26: 493260 | K26: 7773 | AA26: =Z25*Z24 -> 92550.15
D27: Not so liquid | N27: Actual | O27: 31st Dec | P27: 31st Dec | Q27: 31st Dec | R27: 31st Dec | S27: 31st Dec | T27: 31st Dec | Z27: 1.5 | AA27: =AA26/Z27 -> 61700.1
D28: Aston | E28: Sold | G28: 0 | O28: 2015 | P28: 2016 | Q28: 2017 | R28: 2018 | S28: 2019 | T28: 2020 | U28: =T28+1 -> 2021
D29: Golf R | G29: 15000 | N29: Value | O29: 164433.05 | P29: 248589.4 | Q29: 314989.19 | R29: 335945 | S29: 336562 | T29: 374989.19
D30: Motor Bike | G30: 2000 | O30: 0 | P30: 0 | S30: 30000 | T30: 7000
G31: =SUM(G28:G30) -> 17000 | N31: Santandar | O31: 29028
N32: Total | O32: 193461.05 | P32: 248589.4 | Q32: 314989.19 | R32: 335945 | S32: 374989.19 | T32: 381989.19
D33: Less CC Debit | G33: 1600 | P33: 55128.35 | Q33: 66399.786 | R33: =R32-Q32 -> 20955.812
D35: Sub Total | G35: =G26+G31-G33 -> 544948 | N35: Q1 | P35: 282432.89 | Q35: 33843.485 | R35: 8687 | S35: 120736 | Z35: phil | AA35: 1500
N36: Q2 | P36: 294892.7 | Q36: 12459.809 | R36: 5697 | S36: 43735
D37: Tied Assetts | G37: =M24 -> 100500 | N37: Q3 | P37: 310690.69 | Q37: 15797.999 | R37: 37050 | S37: -7000
N38: Q4 | P38: 314989.19 | Q38: 4298.4936 | R38: -31361 | S38: 11634
D39: House | G39: 360000 | Q39: 66399.786 | R39: =SUM(R35:R38) -> 20073 | S39: =SUM(S35:S38) -> 169105
D40: less mortgage | G40: =G39 -> 360000
N41: Budget | O41: 31st Dec | P41: 31st Dec | Q41: 31st Dec | R41: 31st Dec | S41: 31st Dec | T41: 31st Dec | Z41: RN Pension
D42: Nett Worth | G42: =G40+G37+G35 -> 1005448 | O42: 2015 | P42: 2016 | Q42: 2017 | R42: 2018 | S42: 2019 | T42: 2020 | Z42: Nissan | AA42: GSR Capital
...

Sheet 30_06_20
A1: 201
D2: Liquid Assests | G2: Read This | J2: Tied Assests
D3: Prod | E3: Where | F3: Who | H3: 43980 | J3: Prod | K3: Where | L3: Who | M3: Amount | Q3: At Risk | R3: Not a Risk - Cash
B4: =488+743 -> 1231 | D4: ISA | E4: Ford | F4: JG | G4: 53060 | H4: 30657 | J4: Jenny | M4: 0 | Q4: =G24-R4 -> 355563 | R4: =SUM(G11:G15) -> 185100 | T4: 130 | V4: 102.8 | W4: Share Price
B5: =504+803 -> 1307 | D5: ISA | E5: Ford | F5: MG | G5: 53060 | H5: 30657 | J5: Faye | M5: 22000 | P5: this is 17k + 5K | T5: 71 | V5: 1.125 | W5: Exchange | AE5: NSI | AF5: 100000
D6: FundSmith | G6: 8061 | H6: 7491 | J6: Nik | M6: 5000 | N6: 155K | P6: Med | Q6: =G4+G5+G16+G17+G18 -> 333936 | T6: =T4-T5 -> 59 | AE6: Share | AF6: 85000
C7: * | D7: Hargrevaes Lansdown | G7: 1161 | H7: 1091 | P7: High | Q7: =SUM(G6:G10) -> 21627
C8: * | D8: Intractive Investor | G8: 11861 | H8: 10718
C9: * | D9: Bakkovor Now III | G9: 371 | H9: 367 | J9: Les and Jon | M9: 20000
C10: * | D10: Coinbase | G10: 173 | H10: 151 | J10: lister st | M10: 0
D11: Current account - Inv, Currt and Holid | E11: Nat West Invest/Holiday - Not EX, Not Prop, Not Current below 4K | G11: 23600 | H11: 75000 | J11: Phil | M11: 1500 | R11: =14514*2 -> 29028 | AE11: Invest | AF11: 40000
D12: Premium Bonds | E12: Post Office | F12: JG | G12: 50000 | H12: 50000 | J12: House | K12: 2bed | M12: 37000 | AF12: =SUM(AF5:AF11) -> 225000
D13: Premium Bonds | E13: Post Office | F13: BH | G13: 11500 | H13: 11100
D14: Premium Bonds | E14: Post Office | F14: FG | G14: 50000 | H14: 50000 | Q14: 81287
A15: Q3 | B15: Q2 | C15: 2018 | D15: Premium Bonds | E15: Post Office | F15: MG | G15: 50000 | H15: 50000 | J15: House | K15: 3bed | M15: 35000 | Q15: =G4*2 -> 106120
A16: 766 | B16: 766 | C16: 523 | D16: EDSP | E16: Computershare | F16: MG | G16: 87460 | H16: 72611 | J16: Total | M16: =SUM(M4:M15) -> 120500 | N16: 73707 | Q16: =Q14-Q15 -> -24833 | X16: =SUM(A16:A18) -> 1867 | Y16: =X16*V4 -> 191927.6
A17: 504 | B17: 504 | D17: Trading Acocunt | E17: III ( both JG and MG) | F17: MGJG | G17: =27906+29326 -> 57232 | H17: =23291*2 -> 46582
A18: 597 | B18: 555 | C18: 715 | D18: OWN SAP | F18: MG | G18: 83124 | H18: 66216
A19: 2011 | C19: 99 | D19: SAP Shares | E19: 1 free | F19: MG | H19: 33 | J19: SAP Shares | K19: 1 free | N19: 42156 | P19: 37666 | W19: =388*70/1.43 -> 18993.007
A20: 2012 | C20: 96 | D20: SAP Shares | E20: 5 p 3y 3g | F20: MG | H20: 160 | J20: SAP Shares | K20: 5 p 3y 3g | N20: 41791 | P20: 35143
A21: 2013 | C21: 87 | D21: SAP Shares | E21: B3K3G1 | F21: MG | H21: 29 | J21: SAP Shares | K21: B3K3G1 | N21: 42583
M22: =SUM(M19:M21) -> 0
D24: Total | G24: =SUM(G4:G18) -> 540663 | H24: 529548 | I24: 504894 | K24: =G26-H24 -> 11115 | M24: =M16+M22 -> 120500 | Z24: 1155
Q25: 900 | Z25: 80.13
D26: Potential Balance | G26: =G24 -> 540663 | H26: 493260 | K26: 7773 | AA26: =Z25*Z24 -> 92550.15
D27: Not so liquid | N27: Actual | O27: 31st Dec | P27: 31st Dec | Q27: 31st Dec | R27: 31st Dec | S27: 31st Dec | T27: 31st Dec | Z27: 1.5 | AA27: =AA26/Z27 -> 61700.1
D28: Aston | E28: Sold | G28: 0 | O28: 2015 | P28: 2016 | Q28: 2017 | R28: 2018 | S28: 2019 | T28: 2020 | U28: =T28+1 -> 2021
D29: Golf R | G29: 15000 | N29: Value | O29: 164433.05 | P29: 248589.4 | Q29: 314989.19 | R29: 335945 | S29: 336562 | T29: 374989.19
D30: Motor Bike | G30: 2000 | O30: 0 | P30: 0 | S30: 30000 | T30: 7000
G31: =SUM(G28:G30) -> 17000 | N31: Santandar | O31: 29028
N32: Total | O32: 193461.05 | P32: 248589.4 | Q32: 314989.19 | R32: 335945 | S32: 374989.19 | T32: 381989.19
D33: Less CC Debit | G33: 1600 | P33: 55128.35 | Q33: 66399.786 | R33: =R32-Q32 -> 20955.812
D35: Sub Total | G35: =G26+G31-G33 -> 556063 | N35: Q1 | P35: 282432.89 | Q35: 33843.485 | R35: 8687 | S35: 120736 | Z35: phil | AA35: 1500
N36: Q2 | P36: 294892.7 | Q36: 12459.809 | R36: 5697 | S36: 43735
D37: Tied Assetts | G37: =M24 -> 120500 | N37: Q3 | P37: 310690.69 | Q37: 15797.999 | R37: 37050 | S37: -7000
N38: Q4 | P38: 314989.19 | Q38: 4298.4936 | R38: -31361 | S38: 11634
D39: House | G39: 360000 | Q39: 66399.786 | R39: =SUM(R35:R38) -> 20073 | S39: =SUM(S35:S38) -> 169105
D40: less mortgage | G40: =G39 -> 360000
N41: Budget | O41: 31st Dec | P41: 31st Dec | Q41: 31st Dec | R41: 31st Dec | S41: 31st Dec | T41: 31st Dec | Z41: RN Pension
D42: Nett Worth | G42: =G40+G37+G35 -> 1036563 | O42: 2015 | P42: 2016 | Q42: 2017 | R42: 2018 | S42: 2019 | T42: 2020 | Z42: Nissan | AA42: GSR Capital
...

Sheet 31_07_20
A1: 201
D2: Liquid Assests | G2: Read This | J2: Tied Assests
D3: Prod | E3: Where | F3: Who | G3: 31st July | H3: 30th June | J3: Prod | K3: Where | L3: Who | M3: Amount | Q3: At Risk | R3: Not a Risk - Cash
B4: =488+743 -> 1231 | D4: ISA | E4: Ford | F4: JG | G4: 53648 | H4: 53060 | J4: Jenny | M4: 0 | Q4: =G24-R4 -> 372928 | R4: =SUM(G11:G15) -> 186500 | T4: 130 | V4: 102.8 | W4: Share Price
B5: =504+803 -> 1307 | D5: ISA | E5: Ford | F5: MG | G5: 53648 | H5: 53060 | J5: Faye | M5: 22000 | P5: this is 17k + 5K | T5: 71 | V5: 1.125 | W5: Exchange | AE5: NSI | AF5: 100000
D6: FundSmith | G6: 8126 | H6: 8061 | J6: Nik | M6: 5000 | N6: 155K | P6: Med | Q6: =G4+G5+G16+G17+G18 -> 351686 | T6: =T4-T5 -> 59 | AE6: Share | AF6: 85000
C7: * | D7: Hargrevaes Lansdown | G7: 1138 | H7: 1161 | P7: High | Q7: =SUM(G6:G10) -> 21242
C8: * | D8: Intractive Investor | G8: 11397 | H8: 11861
C9: * | D9: Bakkovor Now III | G9: 336 | H9: 371 | J9: Les and Jon | M9: 20000
C10: * | D10: Coinbase | G10: 245 | H10: 173 | J10: lister st | M10: 0
D11: Current account - Inv, Currt and Holid | E11: Nat West Invest/Holiday - Not EX, Not Prop, Not Current below 4K | G11: 25000 | H11: 23600 | J11: Phil | M11: 1500 | R11: =14514*2 -> 29028 | AE11: Invest | AF11: 40000
D12: Premium Bonds | E12: Post Office | F12: JG | G12: 50000 | H12: 50000 | J12: House | K12: 2bed | M12: 37000 | AF12: =SUM(AF5:AF11) -> 225000
D13: Premium Bonds | E13: Post Office | F13: BH | G13: 11500 | H13: 11500
D14: Premium Bonds | E14: Post Office | F14: FG | G14: 50000 | H14: 50000 | Q14: 81287
A15: Q3 | B15: Q2 | C15: 2018 | D15: Premium Bonds | E15: Post Office | F15: MG | G15: 50000 | H15: 50000 | J15: House | K15: 3bed | M15: 35000 | Q15: =G4*2 -> 107296
A16: 766 | B16: 766 | C16: 523 | D16: EDSP | E16: Computershare | F16: MG | G16: 93204 | H16: 87460 | J16: Total | M16: =SUM(M4:M15) -> 120500 | N16: 73707 | Q16: =Q14-Q15 -> -26009 | X16: =SUM(A16:A18) -> 1867 | Y16: =X16*V4 -> 191927.6
A17: 504 | B17: 504 | D17: Trading Acocunt | E17: III ( both JG and MG) | F17: MGJG | G17: =31181+30000 -> 61181 | H17: =27906+29326 -> 57232
A18: 597 | B18: 555 | C18: 715 | D18: OWN SAP | F18: MG | G18: 90005 | H18: 83124
A19: 2011 | C19: 99 | D19: SAP Shares | E19: 1 free | F19: MG | J19: SAP Shares | K19: 1 free | N19: 42156 | P19: 37666 | W19: =388*70/1.43 -> 18993.007
A20: 2012 | C20: 96 | D20: SAP Shares | E20: 5 p 3y 3g | F20: MG | J20: SAP Shares | K20: 5 p 3y 3g | N20: 41791 | P20: 35143
A21: 2013 | C21: 87 | D21: SAP Shares | E21: B3K3G1 | F21: MG | J21: SAP Shares | K21: B3K3G1 | N21: 42583
M22: =SUM(M19:M21) -> 0
D24: Total | G24: =SUM(G4:G18) -> 559428 | H24: 529548 | I24: 504894 | K24: =G26-H24 -> 29880 | M24: =M16+M22 -> 120500 | Z24: 1155
Q25: 900 | Z25: 80.13
D26: Potential Balance | G26: =G24 -> 559428 | H26: 493260 | K26: 7773 | AA26: =Z25*Z24 -> 92550.15
D27: Not so liquid | N27: Actual | O27: 31st Dec | P27: 31st Dec | Q27: 31st Dec | R27: 31st Dec | S27: 31st Dec | T27: 31st Dec | Z27: 1.5 | AA27: =AA26/Z27 -> 61700.1
D28: Aston | E28: Sold | G28: 0 | O28: 2015 | P28: 2016 | Q28: 2017 | R28: 2018 | S28: 2019 | T28: 2020 | U28: =T28+1 -> 2021
D29: Golf R | G29: 15000 | N29: Value | O29: 164433.05 | P29: 248589.4 | Q29: 314989.19 | R29: 335945 | S29: 336562 | T29: 374989.19
D30: Motor Bike | G30: 2000 | O30: 0 | P30: 0 | S30: 30000 | T30: 7000
G31: =SUM(G28:G30) -> 17000 | N31: Santandar | O31: 29028
N32: Total | O32: 193461.05 | P32: 248589.4 | Q32: 314989.19 | R32: 335945 | S32: 374989.19 | T32: 381989.19
D33: Less CC Debit | G33: 1600 | P33: 55128.35 | Q33: 66399.786 | R33: =R32-Q32 -> 20955.812
D35: Sub Total | G35: =G26+G31-G33 -> 574828 | N35: Q1 | P35: 282432.89 | Q35: 33843.485 | R35: 8687 | S35: 120736 | Z35: phil | AA35: 1500
N36: Q2 | P36: 294892.7 | Q36: 12459.809 | R36: 5697 | S36: 43735
D37: Tied Assetts | G37: =M24 -> 120500 | N37: Q3 | P37: 310690.69 | Q37: 15797.999 | R37: 37050 | S37: -7000
N38: Q4 | P38: 314989.19 | Q38: 4298.4936 | R38: -31361 | S38: 11634
D39: House | G39: 360000 | Q39: 66399.786 | R39: =SUM(R35:R38) -> 20073 | S39: =SUM(S35:S38) -> 169105
D40: less mortgage | G40: =G39 -> 360000
N41: Budget | O41: 31st Dec | P41: 31st Dec | Q41: 31st Dec | R41: 31st Dec | S41: 31st Dec | T41: 31st Dec | Z41: RN Pension
D42: Nett Worth | G42: =G40+G37+G35 -> 1055328 | O42: 2015 | P42: 2016 | Q42: 2017 | R42: 2018 | S42: 2019 | T42: 2020 | Z42: Nissan | AA42: GSR Capital
...

Sheet 31_08_20
A1: 201
D2: Liquid Assests | G2: Read This | J2: Tied Assests
D3: Prod | E3: Where | F3: Who | G3: 31st Aug | H3: 31st July | J3: Prod | K3: Where | L3: Who | M3: Amount | Q3: At Risk | R3: Not a Risk - Cash
B4: =488+743 -> 1231 | D4: ISA | E4: Ford | F4: JG | G4: =33591+22023 -> 55614 | H4: 53648 | J4: Jenny | M4: 0 | Q4: =G24-R4 -> 392474 | R4: =SUM(G11:G15) -> 192000 | T4: 130 | V4: 102.8 | W4: Share Price
B5: =504+803 -> 1307 | D5: ISA | E5: Ford | F5: MG | G5: 55491 | H5: 53648 | J5: Faye | M5: 22000 | P5: this is 17k + 5K | T5: 71 | V5: 1.125 | W5: Exchange | AE5: NSI | AF5: 100000
D6: FundSmith | G6: 8469 | H6: 8126 | J6: Nik | M6: 5000 | N6: 155K | P6: Med | Q6: =G5+#REF!+G16+G17+G18 -> #REF! | T6: =T4-T5 -> 59 | AE6: Share | AF6: 85000
C7: * | D7: Hargrevaes Lansdown | G7: 1193 | H7: 1138 | P7: High | Q7: =SUM(G6:G10) -> 21793
C8: * | D8: Intractive Investor | G8: 11541 | H8: 11397
C9: * | D9: Bakkovor Now III | G9: 312 | H9: 336 | J9: Les and Jon | M9: 20000
C10: * | D10: Coinbase | G10: 278 | H10: 245 | J10: lister st | M10: 0
D11: Current account - Inv, Currt and Holid | E11: Nat West Invest/Holiday - Not EX, Not Prop, Not Current below 4K | G11: 42000 | H11: 25000 | J11: Phil | M11: 1500 | R11: =14514*2 -> 29028 | AE11: Invest | AF11: 40000
D12: Premium Bonds | E12: Post Office | F12: JG | G12: 50000 | H12: 50000 | J12: House | K12: 2bed | M12: 37000 | AF12: =SUM(AF5:AF11) -> 225000
D13: Premium Bonds | E13: Post Office | F13: BH | G13: 0 | H13: 11500
D14: Premium Bonds | E14: Post Office | F14: FG | G14: 50000 | H14: 50000 | Q14: 81287
A15: Q3 | B15: Q2 | C15: 2018 | D15: Premium Bonds | E15: Post Office | F15: MG | G15: 50000 | H15: 50000 | J15: House | K15: 3bed | M15: 35000 | Q15: =G5*2 -> 110982
A16: 766 | B16: 766 | C16: 774 | D16: EDSP | E16: Computershare | F16: MG | G16: 96526 | H16: 93204 | J16: Total | M16: =SUM(M4:M15) -> 120500 | N16: 73707 | Q16: =Q14-Q15 -> -29695 | X16: =SUM(A16:A18) -> 1867 | Y16: =X16*V4 -> 191927.6
A17: 504 | B17: 504 | D17: Trading Acocunt | E17: III ( both JG and MG) | F17: MGJG | G17: =30791+235+32292 -> 63318 | H17: =31181+30000 -> 61181
A18: 597 | B18: 555 | C18: 759 | D18: OWN SAP | F18: MG | G18: 99732 | H18: 90005
A19: 2011 | C19: 99 | D19: SAP Shares | E19: 1 free | F19: MG | J19: SAP Shares | K19: 1 free | N19: 42156 | P19: 37666 | W19: =388*70/1.43 -> 18993.007
A20: 2012 | C20: 96 | D20: SAP Shares | E20: 5 p 3y 3g | F20: MG | J20: SAP Shares | K20: 5 p 3y 3g | N20: 41791 | P20: 35143
A21: 2013 | C21: 87 | D21: SAP Shares | E21: B3K3G1 | F21: MG | J21: SAP Shares | K21: B3K3G1 | N21: 42583
M22: =SUM(M19:M21) -> 0
D24: Total | G24: =SUM(G4:G18) -> 584474 | H24: =SUM(H4:H18) -> 559428 | I24: 504894 | K24: =G26-H24 -> 25046 | M24: =M16+M22 -> 120500 | Z24: 1155
Q25: 900 | Z25: 80.13
D26: Potential Balance | G26: =G24 -> 584474 | H26: 493260 | I26: =G24-H24 -> 25046 | K26: 7773 | AA26: =Z25*Z24 -> 92550.15
D27: Not so liquid | N27: Actual | O27: 31st Dec | P27: 31st Dec | Q27: 31st Dec | R27: 31st Dec | S27: 31st Dec | T27: 31st Dec | Z27: 1.5 | AA27: =AA26/Z27 -> 61700.1
D28: Aston | E28: Sold | G28: 0 | O28: 2015 | P28: 2016 | Q28: 2017 | R28: 2018 | S28: 2019 | T28: 2020 | U28: =T28+1 -> 2021
D29: Golf R | G29: 15000 | N29: Value | O29: 164433.05 | P29: 248589.4 | Q29: 314989.19 | R29: 335945 | S29: 336562 | T29: 374989.19
D30: Motor Bike | G30: 2000 | O30: 0 | P30: 0 | S30: 30000 | T30: 7000
G31: =SUM(G28:G30) -> 17000 | N31: Santandar | O31: 29028
N32: Total | O32: 193461.05 | P32: 248589.4 | Q32: 314989.19 | R32: 335945 | S32: 374989.19 | T32: 381989.19
D33: Less CC Debit | G33: 1600 | P33: 55128.35 | Q33: 66399.786 | R33: =R32-Q32 -> 20955.812
D35: Sub Total | G35: =G26+G31-G33 -> 599874 | N35: Q1 | P35: 282432.89 | Q35: 33843.485 | R35: 8687 | S35: 120736 | Z35: phil | AA35: 1500
N36: Q2 | P36: 294892.7 | Q36: 12459.809 | R36: 5697 | S36: 43735
D37: Tied Assetts | G37: =M24 -> 120500 | N37: Q3 | P37: 310690.69 | Q37: 15797.999 | R37: 37050 | S37: -7000
N38: Q4 | P38: 314989.19 | Q38: 4298.4936 | R38: -31361 | S38: 11634
D39: House | G39: 360000 | Q39: 66399.786 | R39: =SUM(R35:R38) -> 20073 | S39: =SUM(S35:S38) -> 169105
D40: less mortgage | G40: =G39 -> 360000
N41: Budget | O41: 31st Dec | P41: 31st Dec | Q41: 31st Dec | R41: 31st Dec | S41: 31st Dec | T41: 31st Dec | Z41: RN Pension
D42: Nett Worth | G42: =G40+G37+G35 -> 1080374 | O42: 2015 | P42: 2016 | Q42: 2017 | R42: 2018 | S42: 2019 | T42: 2020 | Z42: Nissan | AA42: GSR Capital
...

Sheet 01_10_20
A1: 201
D2: Liquid Assests | G2: Read This | J2: Tied Assests
D3: Prod | E3: Where | F3: Who | G3: 1st October | H3: 31st Aug | J3: Prod | K3: Where | L3: Who | M3: Amount | Q3: At Risk | R3: Not a Risk - Cash
B4: =488+743 -> 1231 | D4: ISA | E4: Ford | F4: JG | G4: 55221 | H4: =33591+22023 -> 55614 | J4: Jenny | M4: 0 | Q4: =G24-R4 -> 382859.99 | R4: =SUM(G11:G15) -> 192000 | T4: 130 | V4: 102.8 | W4: Share Price
B5: =504+803 -> 1307 | D5: ISA | E5: Ford | F5: MG | G5: 55221 | H5: 55491 | J5: Faye | M5: 22000 | P5: this is 17k + 5K | T5: 71 | V5: 1.125 | W5: Exchange | AE5: NSI | AF5: 100000
D6: FundSmith | G6: 8580 | H6: 8469 | J6: Nik | M6: 5000 | N6: 155K | P6: Med | Q6: =#REF!+#REF!+G16+G17+G18 -> #REF! | T6: =T4-T5 -> 59 | AE6: Share | AF6: 85000
C7: * | D7: Hargrevaes Lansdown | G7: 1348 | H7: 1193 | P7: High | Q7: =SUM(G6:G10) -> 22076
C8: * | D8: Intractive Investor | G8: 11545 | H8: 11541
C9: * | D9: Bakkovor Now III | G9: 343 | H9: 312 | J9: Les and Jon | M9: 20000
C10: * | D10: Coinbase | G10: 260 | H10: 278 | J10: lister st | M10: 0
D11: Current account - Inv, Currt and Holid | E11: Nat West Invest/Holiday - Not EX, Not Prop, Not Current below 4K | G11: 42000 | H11: 42000 | J11: Phil | M11: 1500 | R11: =14514*2 -> 29028 | AE11: Invest | AF11: 40000
D12: Premium Bonds | E12: Post Office | F12: JG | G12: 50000 | H12: 50000 | J12: House | K12: 2bed | M12: 38000 | AF12: =SUM(AF5:AF11) -> 225000
D13: Premium Bonds | E13: Post Office | F13: BH | G13: 0 | H13: 0
D14: Premium Bonds | E14: Post Office | F14: FG | G14: 50000 | H14: 50000 | Q14: 81287
A15: Q3 | B15: Q2 | C15: 2018 | D15: Premium Bonds | E15: Post Office | F15: MG | G15: 50000 | H15: 50000 | J15: House | K15: 3bed | M15: 36000 | Q15: =#REF!*2 -> #REF!
A16: 766 | B16: 766 | C16: 774 | D16: EDSP | E16: Computershare | F16: MG | G16: 94346.65 | H16: 96526 | J16: Total | M16: =SUM(M4:M15) -> 122500 | N16: 73707 | Q16: =Q14-Q15 -> #REF! | X16: =SUM(A16:A18) -> 1867 | Y16: =X16*V4 -> 191927.6
A17: 504 | B17: 504 | D17: Trading Acocunt | E17: III ( both JG and MG) | F17: MGJG | G17: =231+30104+31578 -> 61913 | H17: =30791+235+32292 -> 63318
A18: 597 | B18: 555 | C18: 772 | D18: OWN SAP | F18: MG | G18: 94082.34 | H18: 99732
A19: 2011 | C19: 99 | D19: SAP Shares | E19: 1 free | F19: MG | J19: SAP Shares | K19: 1 free | N19: 42156 | P19: 37666 | W19: =388*70/1.43 -> 18993.007
A20: 2012 | C20: 96 | D20: SAP Shares | E20: 5 p 3y 3g | F20: MG | J20: SAP Shares | K20: 5 p 3y 3g | N20: 41791 | P20: 35143
A21: 2013 | C21: 87 | D21: SAP Shares | E21: B3K3G1 | F21: MG | J21: SAP Shares | K21: B3K3G1 | N21: 42583
M22: =SUM(M19:M21) -> 0
D24: Total | G24: =SUM(G4:G18) -> 574859.99 | H24: =SUM(H4:H18) -> 584474 | I24: 504894 | K24: =G26-H24 -> -9614.01 | M24: =M16+M22 -> 122500 | Z24: 1155
Q25: 900 | Z25: 80.13
D26: Potential Balance | G26: =G24 -> 574859.99 | H26: 584474 | I26: =G24-H24 -> -9614.01 | K26: 7773 | AA26: =Z25*Z24 -> 92550.15
D27: Not so liquid | N27: Actual | O27: 31st Dec | P27: 31st Dec | Q27: 31st Dec | R27: 31st Dec | S27: 31st Dec | T27: 31st Dec | Z27: 1.5 | AA27: =AA26/Z27 -> 61700.1
D28: Aston | E28: Sold | G28: 0 | O28: 2015 | P28: 2016 | Q28: 2017 | R28: 2018 | S28: 2019 | T28: 2020 | U28: =T28+1 -> 2021
D29: Golf R | G29: 15000 | N29: Value | O29: 164433.05 | P29: 248589.4 | Q29: 314989.19 | R29: 335945 | S29: 336562 | T29: 374989.19
D30: Motor Bike | G30: 2000 | O30: 0 | P30: 0 | S30: 30000 | T30: 7000
G31: =SUM(G28:G30) -> 17000 | N31: Santandar | O31: 29028
N32: Total | O32: 193461.05 | P32: 248589.4 | Q32: 314989.19 | R32: 335945 | S32: 374989.19 | T32: 381989.19
D33: Less CC Debit | G33: 1600 | P33: 55128.35 | Q33: 66399.786 | R33: =R32-Q32 -> 20955.812
D35: Sub Total | G35: =G26+G31-G33 -> 590259.99 | N35: Q1 | P35: 282432.89 | Q35: 33843.485 | R35: 8687 | S35: 120736 | Z35: phil | AA35: 1500
N36: Q2 | P36: 294892.7 | Q36: 12459.809 | R36: 5697 | S36: 43735
D37: Tied Assetts | G37: =M24 -> 122500 | N37: Q3 | P37: 310690.69 | Q37: 15797.999 | R37: 37050 | S37: -7000
N38: Q4 | P38: 314989.19 | Q38: 4298.4936 | R38: -31361 | S38: 11634
D39: House | G39: 360000 | Q39: 66399.786 | R39: =SUM(R35:R38) -> 20073 | S39: =SUM(S35:S38) -> 169105
D40: less mortgage | G40: =G39 -> 360000
N41: Budget | O41: 31st Dec | P41: 31st Dec | Q41: 31st Dec | R41: 31st Dec | S41: 31st Dec | T41: 31st Dec | Z41: RN Pension
D42: Nett Worth | G42: =G40+G37+G35 -> 1072760 | O42: 2015 | P42: 2016 | Q42: 2017 | R42: 2018 | S42: 2019 | T42: 2020 | Z42: Nissan | AA42: GSR Capital
...

Sheet 30-10-20
A1: 201
D2: Liquid Assests | G2: Read This | J2: Tied Assests
D3: Prod | E3: Where | F3: Who | G3: 44134 | H3: 1st October | J3: Prod | K3: Where | L3: Who | M3: Amount | Q3: At Risk | R3: Not a Risk - Cash
B4: =488+743 -> 1231 | D4: ISA | E4: Ford | F4: JG | G4: =32582+21348 -> 53930 | H4: 55221 | J4: Jenny | M4: 0 | Q4: =G24-R4 -> 300299 | R4: =SUM(G11:G15) -> 193427 | T4: 130 | V4: 102.8 | W4: Share Price
B5: =504+803 -> 1307 | D5: ISA | E5: Ford | F5: MG | G5: 53930 | H5: 55221 | J5: Faye | M5: 22000 | P5: this is 17k + 5K | T5: 71 | V5: 1.125 | W5: Exchange | AE5: NSI | AF5: 100000
D6: FundSmith | G6: 8307 | H6: 8580 | J6: Nik | M6: 5000 | N6: 155K | P6: Med | Q6: =#REF!+#REF!+G16+G17+G18 -> #REF! | T6: =T4-T5 -> 59 | AE6: Share | AF6: 85000
C7: * | D7: Hargrevaes Lansdown | G7: 1346 | H7: 1348 | P7: High | Q7: =SUM(G6:G10) -> 22260
C8: * | D8: Intractive Investor | G8: 12020 | H8: 11545
C9: * | D9: Bakkovor Now III | G9: 310 | H9: 343 | J9: Les and Jon | M9: 20000
C10: * | D10: Coinbase | G10: 277 | H10: 260 | J10: lister st | M10: 0
D11: Current account - Inv, Currt and Holid | E11: Nat West Invest/Holiday - Not EX, Not Prop, Not Current below 4K | G11: 43427 | H11: 42000 | J11: Phil | M11: 1500 | R11: =14514*2 -> 29028 | AE11: Invest | AF11: 40000
D12: Premium Bonds | E12: Post Office | F12: JG | G12: 50000 | H12: 50000 | J12: House | K12: 2bed | M12: 38000 | AF12: =SUM(AF5:AF11) -> 225000
D13: Premium Bonds | E13: Post Office | F13: BH | H13: 0
D14: Premium Bonds | E14: Post Office | F14: FG | G14: 50000 | H14: 50000 | Q14: 81287
A15: Q3 | B15: Q2 | C15: 2018 | D15: Premium Bonds | E15: Post Office | F15: MG | G15: 50000 | H15: 50000 | J15: House | K15: 3bed | M15: 36000 | Q15: =#REF!*2 -> #REF!
A16: 766 | B16: 766 | C16: 774 | D16: EDSP | E16: Computershare | F16: MG | G16: 63712 | H16: 94346.65 | J16: Total | M16: =SUM(M4:M15) -> 122500 | N16: 73707 | Q16: =Q14-Q15 -> #REF! | X16: =SUM(A16:A18) -> 1867 | Y16: =X16*V4 -> 191927.6
A17: 504 | B17: 504 | D17: Trading Acocunt | E17: III ( both JG and MG) | F17: MGJG | G17: =20336+206+21377 -> 41919 | H17: =231+30104+31578 -> 61913
A18: 597 | B18: 555 | C18: 772 | D18: OWN SAP | F18: MG | G18: 64548 | H18: 94082.34
A19: 2011 | C19: 99 | D19: SAP Shares | E19: 1 free | F19: MG | J19: SAP Shares | K19: 1 free | N19: 42156 | P19: 37666 | W19: =388*70/1.43 -> 18993.007
A20: 2012 | C20: 96 | D20: SAP Shares | E20: 5 p 3y 3g | F20: MG | J20: SAP Shares | K20: 5 p 3y 3g | N20: 41791 | P20: 35143
A21: 2013 | C21: 87 | D21: SAP Shares | E21: B3K3G1 | F21: MG | J21: SAP Shares | K21: B3K3G1 | N21: 42583
M22: =SUM(M19:M21) -> 0
D24: Total | G24: =SUM(G4:G18) -> 493726 | H24: =SUM(H4:H18) -> 574859.99 | I24: 504894 | K24: =G26-H24 -> -81133.99 | M24: =M16+M22 -> 122500 | Z24: 1155
Q25: 900 | Z25: 80.13
D26: Potential Balance | G26: =G24 -> 493726 | H26: 584474 | I26: =G24-H24 -> -81133.99 | K26: 7773 | AA26: =Z25*Z24 -> 92550.15
D27: Not so liquid | N27: Actual | O27: 31st Dec | P27: 31st Dec | Q27: 31st Dec | R27: 31st Dec | S27: 31st Dec | T27: 31st Dec | Z27: 1.5 | AA27: =AA26/Z27 -> 61700.1
D28: Aston | E28: Sold | G28: 0 | O28: 2015 | P28: 2016 | Q28: 2017 | R28: 2018 | S28: 2019 | T28: 2020 | U28: =T28+1 -> 2021
D29: Golf R | G29: 15000 | N29: Value | O29: 164433.05 | P29: 248589.4 | Q29: 314989.19 | R29: 335945 | S29: 336562 | T29: 374989.19
D30: Motor Bike | G30: 2000 | O30: 0 | P30: 0 | S30: 30000 | T30: 7000
G31: =SUM(G28:G30) -> 17000 | N31: Santandar | O31: 29028
N32: Total | O32: 193461.05 | P32: 248589.4 | Q32: 314989.19 | R32: 335945 | S32: 374989.19 | T32: 381989.19
D33: Less CC Debit | G33: 1600 | P33: 55128.35 | Q33: 66399.786 | R33: =R32-Q32 -> 20955.812
D35: Sub Total | G35: =G26+G31-G33 -> 509126 | N35: Q1 | P35: 282432.89 | Q35: 33843.485 | R35: 8687 | S35: 120736 | Z35: phil | AA35: 1500
N36: Q2 | P36: 294892.7 | Q36: 12459.809 | R36: 5697 | S36: 43735
D37: Tied Assetts | G37: =M24 -> 122500 | N37: Q3 | P37: 310690.69 | Q37: 15797.999 | R37: 37050 | S37: -7000
N38: Q4 | P38: 314989.19 | Q38: 4298.4936 | R38: -31361 | S38: 11634
D39: House | G39: 360000 | Q39: 66399.786 | R39: =SUM(R35:R38) -> 20073 | S39: =SUM(S35:S38) -> 169105
D40: less mortgage | G40: =G39 -> 360000
N41: Budget | O41: 31st Dec | P41: 31st Dec | Q41: 31st Dec | R41: 31st Dec | S41: 31st Dec | T41: 31st Dec | Z41: RN Pension
D42: Nett Worth | G42: =G40+G37+G35 -> 991626 | O42: 2015 | P42: 2016 | Q42: 2017 | R42: 2018 | S42: 2019 | T42: 2020 | Z42: Nissan | AA42: GSR Capital
...

Sheet 30-11-20
A1: 201
D2: Liquid Assests | G2: Read This | J2: Tied Assests
D3: Prod | E3: Where | F3: Who | G3: 44165 | H3: 44134 | J3: Prod | K3: Where | L3: Who | M3: Amount | Q3: At Risk | R3: Not a Risk - Cash
B4: =488+743 -> 1231 | D4: ISA | E4: Ford | F4: JG | G4: 57186 | H4: =32582+21348 -> 53930 | J4: Jenny | M4: 0 | Q4: =G24-R4 -> 333420 | R4: =SUM(G11:G15) -> 185700 | T4: 130 | V4: 102.8 | W4: Share Price
B5: =504+803 -> 1307 | D5: ISA | E5: Ford | F5: MG | G5: 57186 | H5: 53930 | J5: Faye | M5: 22000 | P5: this is 17k + 5K | T5: 71 | V5: 1.125 | W5: Exchange | AE5: NSI | AF5: 100000
D6: FundSmith | G6: 8712 | H6: 8307 | J6: Nik | M6: 5000 | N6: 155K | P6: Med | Q6: =#REF!+#REF!+G16+G17+G18 -> #REF! | T6: =T4-T5 -> 59 | AE6: Share | AF6: 85000
C7: * | D7: Hargrevaes Lansdown | G7: 1488 | H7: 1346 | P7: High | Q7: =SUM(G6:G10) -> 28688
C8: * | D8: Intractive Investor | G8: 15053 | H8: 12020
C9: * | D9: Bakkovor Now III | G9: 435 | H9: 310 | J9: Les and Jon | M9: 20000
C10: * | D10: Now CfD | G10: 3000 | H10: 277 | J10: lister st | M10: 0
D11: Current account - Inv, Currt and Holid | E11: Nat West Invest/Holiday - Not EX, Not Prop, Not Current below 4K | G11: 35700 | H11: 43427 | J11: Phil | M11: 1500 | R11: =14514*2 -> 29028 | AE11: Invest | AF11: 40000
D12: Premium Bonds | E12: Post Office | F12: JG | G12: 50000 | H12: 50000 | J12: House | K12: 2bed | M12: 38000 | AF12: =SUM(AF5:AF11) -> 225000
D13: Premium Bonds | E13: Post Office | F13: BH
D14: Premium Bonds | E14: Post Office | F14: FG | G14: 50000 | H14: 50000 | Q14: 81287
A15: Q3 | B15: Q2 | C15: 2018 | D15: Premium Bonds | E15: Post Office | F15: MG | G15: 50000 | H15: 50000 | J15: House | K15: 3bed | M15: 36000 | Q15: =#REF!*2 -> #REF!
A16: 766 | B16: 766 | C16: 774 | D16: EDSP | E16: Computershare | F16: MG | G16: 70709 | H16: 63712 | J16: Total | M16: =SUM(M4:M15) -> 122500 | N16: 73707 | Q16: =Q14-Q15 -> #REF! | X16: =SUM(A16:A18) -> 1867 | Y16: =X16*V4 -> 191927.6
A17: 504 | B17: 504 | D17: Trading Acocunt | E17: III ( both JG and MG) | F17: MGJG | G17: =(23229-G9)+23723 -> 46517 | H17: =20336+206+21377 -> 41919
A18: 597 | B18: 555 | C18: 800 | D18: OWN SAP | F18: MG | G18: 73134 | H18: 64548
A19: 2011 | C19: 99 | D19: SAP Shares | E19: 1 free | F19: MG | J19: SAP Shares | K19: 1 free | N19: 42156 | P19: 37666 | W19: =388*70/1.43 -> 18993.007
A20: 2012 | C20: 96 | D20: SAP Shares | E20: 5 p 3y 3g | F20: MG | J20: SAP Shares | K20: 5 p 3y 3g | N20: 41791 | P20: 35143
A21: 2013 | C21: 87 | D21: SAP Shares | E21: B3K3G1 | F21: MG | J21: SAP Shares | K21: B3K3G1 | N21: 42583
M22: =SUM(M19:M21) -> 0
D24: Total | G24: =SUM(G4:G18) -> 519120 | H24: =SUM(H4:H18) -> 493726 | I24: 504894 | K24: =G26-H24 -> 25394 | M24: =M16+M22 -> 122500 | Z24: 1155
Q25: 900 | Z25: 80.13
D26: Potential Balance | G26: =G24 -> 519120 | H26: 584474 | I26: =G24-H24 -> 25394 | K26: 7773 | AA26: =Z25*Z24 -> 92550.15
D27: Not so liquid | N27: Actual | O27: 31st Dec | P27: 31st Dec | Q27: 31st Dec | R27: 31st Dec | S27: 31st Dec | T27: 31st Dec | Z27: 1.5 | AA27: =AA26/Z27 -> 61700.1
D28: Aston | E28: Sold | G28: 0 | O28: 2015 | P28: 2016 | Q28: 2017 | R28: 2018 | S28: 2019 | T28: 2020 | U28: =T28+1 -> 2021
D29: Golf R | G29: 15000 | N29: Value | O29: 164433.05 | P29: 248589.4 | Q29: 314989.19 | R29: 335945 | S29: 336562 | T29: 374989.19
D30: Motor Bike | G30: 2000 | O30: 0 | P30: 0 | S30: 30000 | T30: 7000
G31: =SUM(G28:G30) -> 17000 | N31: Santandar | O31: 29028
N32: Total | O32: 193461.05 | P32: 248589.4 | Q32: 314989.19 | R32: 335945 | S32: 374989.19 | T32: 381989.19
D33: Less CC Debit | G33: 1600 | P33: 55128.35 | Q33: 66399.786 | R33: =R32-Q32 -> 20955.812
D35: Sub Total | G35: =G26+G31-G33 -> 534520 | N35: Q1 | P35: 282432.89 | Q35: 33843.485 | R35: 8687 | S35: 120736 | Z35: phil | AA35: 1500
N36: Q2 | P36: 294892.7 | Q36: 12459.809 | R36: 5697 | S36: 43735
D37: Tied Assetts | G37: =M24 -> 122500 | N37: Q3 | P37: 310690.69 | Q37: 15797.999 | R37: 37050 | S37: -7000
N38: Q4 | P38: 314989.19 | Q38: 4298.4936 | R38: -31361 | S38: 11634
D39: House | G39: 360000 | Q39: 66399.786 | R39: =SUM(R35:R38) -> 20073 | S39: =SUM(S35:S38) -> 169105
D40: less mortgage | G40: =G39 -> 360000
N41: Budget | O41: 31st Dec | P41: 31st Dec | Q41: 31st Dec | R41: 31st Dec | S41: 31st Dec | T41: 31st Dec | Z41: RN Pension
D42: Nett Worth | G42: =G40+G37+G35 -> 1017020 | O42: 2015 | P42: 2016 | Q42: 2017 | R42: 2018 | S42: 2019 | T42: 2020 | Z42: Nissan | AA42: GSR Capital
...

Sheet 31-12-20
A1: 201
D2: Liquid Assests | G2: Read This | J2: Tied Assests
D3: Prod | E3: Where | F3: Who | G3: 31/21/2020 | H3: 44165 | J3: Prod | K3: Where | L3: Who | M3: Amount | Q3: At Risk | R3: Not a Risk - Cash
B4: =488+743 -> 1231 | D4: ISA | E4: Ford | F4: JG | G4: 58971 | H4: 57186 | J4: Family Loans | Q4: =G24-R4 -> 352798 | R4: =SUM(G11:G15) -> 183948 | T4: 130 | V4: 102.8 | W4: Share Price
B5: =504+803 -> 1307 | D5: ISA | E5: Ford | F5: MG | G5: 58971 | H5: 57186 | J5: Faye | M5: 22000 | P5: this is 17k + 5K | T5: 71 | V5: 1.125 | W5: Exchange | AE5: NSI | AF5: 100000
D6: FundSmith | G6: 8862 | H6: 8712 | J6: Nik | M6: 5000 | N6: 155K | P6: Med | Q6: =#REF!+#REF!+G16+G17+G18 -> #REF! | T6: =T4-T5 -> 59 | AE6: Share | AF6: 85000
C7: * | D7: Hargrevaes Lansdown | G7: 1439 | H7: 1488 | J7: Les and Jon | M7: 20000 | P7: High | Q7: =SUM(G6:G10) -> 31952
C8: * | D8: Intractive Investor | G8: 19009 | H8: 15053 | J8: Phil | M8: 1500
C9: * | D9: Bakkovor Now III | G9: 426 | H9: 435 | M9: =SUM(M5:M8) -> 48500
C10: * | D10: Now CfD | G10: 2216 | H10: 3000
D11: Current account - Inv, Currt and Holid | E11: Nat West Invest/Holiday - Not EX, Not Prop, Not Current below 4K | G11: 33948 | H11: 35700 | R11: =14514*2 -> 29028 | AE11: Invest | AF11: 40000
D12: Premium Bonds | E12: Post Office | F12: JG | G12: 50000 | H12: 50000 | AF12: =SUM(AF5:AF11) -> 225000
D13: Premium Bonds | E13: Post Office | F13: BH | J13: Rented Properties
D14: Premium Bonds | E14: Post Office | F14: FG | G14: 50000 | H14: 50000 | J14: House | K14: 2bed | M14: 38000 | Q14: 81287
A15: Q3 | B15: Q2 | C15: 2018 | D15: Premium Bonds | E15: Post Office | F15: MG | G15: 50000 | H15: 50000 | J15: House | K15: 3bed | M15: 36000 | Q15: =#REF!*2 -> #REF!
A16: 766 | B16: 766 | C16: 774 | D16: EDSP | E16: Computershare | F16: MG | G16: 74852 | H16: 70709 | J16: Total | M16: =SUM(M14:M15) -> 74000 | N16: 73707 | Q16: =Q14-Q15 -> #REF! | X16: =SUM(A16:A18) -> 1867 | Y16: =X16*V4 -> 191927.6
A17: 504 | B17: 504 | D17: Trading Acocunt | E17: III ( both JG and MG) | F17: MGJG | G17: =(24473-G9)+25001 -> 49048 | H17: =(23229-H9)+23723 -> 46517
A18: 597 | B18: 555 | C18: 800 | D18: OWN SAP | F18: MG | G18: 79004 | H18: 73134
A19: 2011 | C19: 99 | D19: SAP Shares | E19: 1 free | F19: MG | J19: SAP Shares | K19: 1 free | N19: 42156 | P19: 37666 | W19: =388*70/1.43 -> 18993.007
A20: 2012 | C20: 96 | D20: SAP Shares | E20: 5 p 3y 3g | F20: MG | J20: SAP Shares | K20: 5 p 3y 3g | N20: 41791 | P20: 35143
A21: 2013 | C21: 87 | D21: SAP Shares | E21: B3K3G1 | F21: MG | J21: SAP Shares | K21: B3K3G1 | N21: 42583
M22: =SUM(M19:M21) -> 0
D24: Total | G24: =SUM(G4:G18) -> 536746 | H24: =SUM(H4:H18) -> 519120 | I24: 504894 | M24: =M9+M16 -> 122500 | Z24: 1155
Q25: 900 | Z25: 80.13
D26: Potential Balance | G26: =G24 -> 536746 | H26: 584474 | I26: =G24-H24 -> 17626 | K26: 77 | AA26: =Z25*Z24 -> 92550.15
D27: Not so liquid | N27: Actual | O27: 31st Dec | P27: 31st Dec | Q27: 31st Dec | R27: 31st Dec | S27: 31st Dec | T27: 31st Dec | Z27: 1.5 | AA27: =AA26/Z27 -> 61700.1
D28: Aston | E28: Sold | G28: 0 | O28: 2015 | P28: 2016 | Q28: 2017 | R28: 2018 | S28: 2019 | T28: 2020 | U28: =T28+1 -> 2021
D29: Golf R | G29: 15000 | N29: Value | O29: 164433.05 | P29: 248589.4 | Q29: 314989.19 | R29: 335945 | S29: 336562 | T29: 374989.19
D30: Motor Bike | G30: 2000 | O30: 0 | P30: 0 | S30: 30000 | T30: 7000
G31: =SUM(G28:G30) -> 17000 | N31: Santandar | O31: 29028
N32: Total | O32: 193461.05 | P32: 248589.4 | Q32: 314989.19 | R32: 335945 | S32: 374989.19 | T32: 381989.19
D33: Less CC Debit | G33: 1600 | P33: 55128.35 | Q33: 66399.786 | R33: =R32-Q32 -> 20955.812
D35: Sub Total | G35: =G26+G31-G33 -> 552146 | N35: Q1 | P35: 282432.89 | Q35: 33843.485 | R35: 8687 | S35: 120736 | Z35: phil | AA35: 1500
N36: Q2 | P36: 294892.7 | Q36: 12459.809 | R36: 5697 | S36: 43735
D37: Tied Assetts | G37: =M24 -> 122500 | N37: Q3 | P37: 310690.69 | Q37: 15797.999 | R37: 37050 | S37: -7000
N38: Q4 | P38: 314989.19 | Q38: 4298.4936 | R38: -31361 | S38: 11634
D39: House | G39: 360000 | Q39: 66399.786 | R39: =SUM(R35:R38) -> 20073 | S39: =SUM(S35:S38) -> 169105
D40: less mortgage | G40: =G39 -> 360000
N41: Budget | O41: 31st Dec | P41: 31st Dec | Q41: 31st Dec | R41: 31st Dec | S41: 31st Dec | T41: 31st Dec | Z41: RN Pension
D42: Nett Worth | G42: =G40+G37+G35 -> 1034646 | O42: 2015 | P42: 2016 | Q42: 2017 | R42: 2018 | S42: 2019 | T42: 2020 | Z42: Nissan | AA42: GSR Capital
...

Sheet 31-01-21
A1: 201
D2: Liquid Assests | G2: Read This | J2: Tied Assests
D3: Prod | E3: Where | F3: Who | G3: 44227 | H3: 31/21/2020 | J3: Prod | K3: Where | L3: Who | M3: Amount | Q3: At Risk | R3: Not a Risk - Cash
B4: =488+743 -> 1231 | D4: ISA | E4: Ford | F4: JG | G4: 58600 | H4: 58971 | J4: Family Loans | Q4: =G25-R4 -> 367559 | R4: =SUM(G12:G16) -> 158000 | T4: 130 | V4: 102.8 | W4: Share Price
B5: =504+803 -> 1307 | D5: ISA | E5: Ford | F5: MG | G5: 58600 | H5: 58971 | J5: Faye | M5: 22000 | P5: this is 17k + 5K | T5: 71 | V5: 1.125 | W5: Exchange | AE5: NSI | AF5: 100000
D6: FundSmith | G6: 8661 | H6: 8862 | J6: Nik | M6: 5000 | N6: 155K | P6: Med | Q6: =#REF!+#REF!+G17+G18+G19 -> #REF! | T6: =T4-T5 -> 59 | AE6: Share | AF6: 85000
C7: * | D7: Hargrevaes Lansdown | G7: 1414 | H7: 1439 | J7: Les and Jon | M7: 20000 | P7: High | Q7: =SUM(G6:G10) -> 30799
C8: * | D8: Intractive Investor | G8: 18865 | H8: 19009 | J8: Phil | M8: 1500
C9: * | D9: Bakkovor Now III | G9: 439 | H9: 426 | M9: =SUM(M5:M8) -> 48500
C10: * | D10: Now CfD | G10: 1420 | H10: 2216
D11: ClearWaterCapital | G11: 23024
D12: Current account - Inv, Currt and Holid | E12: Nat West Invest/Holiday - Not EX, Not Prop, Not Current below 4K | G12: 8000 | H12: 33948 | R12: =14514*2 -> 29028 | AE12: Invest | AF12: 40000
D13: Premium Bonds | E13: Post Office | F13: JG | G13: 50000 | H13: 50000 | AF13: =SUM(AF5:AF12) -> 225000
D14: Premium Bonds | E14: Post Office | F14: BH | J14: Rented Properties
C15: 105.06 | D15: Premium Bonds | E15: Post Office | F15: FG | G15: 50000 | H15: 50000 | J15: House | K15: 2bed | M15: 38000 | Q15: 81287
A16: Q3 | B16: Q2 | C16: 44227 | D16: Premium Bonds | E16: Post Office | F16: MG | G16: 50000 | H16: 50000 | J16: House | K16: 3bed | M16: 36000 | Q16: =#REF!*2 -> #REF!
A17: 766 | B17: 766 | C17: 774 | D17: EDSP | E17: Computershare | F17: MG | G17: 71991 | H17: 74852 | J17: Total | M17: =SUM(M15:M16) -> 74000 | N17: 73707 | Q17: =Q15-Q16 -> #REF! | X17: =SUM(A17:A19) -> 1867 | Y17: =X17*V4 -> 191927.6
A18: 504 | B18: 504 | D18: Trading Acocunt | E18: III ( both JG and MG) | F18: MGJG | G18: =22892+217+24043 -> 47152 | H18: =(24473-H9)+25001 -> 49048
A19: 597 | B19: 555 | C19: 832 | D19: OWN SAP | F19: MG | G19: 77393 | H19: 79004
A20: 2011 | C20: 99 | D20: SAP Shares | E20: 1 free | F20: MG | J20: SAP Shares | K20: 1 free | N20: 42156 | P20: 37666 | W20: =388*70/1.43 -> 18993.007
A21: 2012 | C21: 96 | D21: SAP Shares | E21: 5 p 3y 3g | F21: MG | J21: SAP Shares | K21: 5 p 3y 3g | N21: 41791 | P21: 35143
A22: 2013 | C22: 87 | D22: SAP Shares | E22: B3K3G1 | F22: MG | J22: SAP Shares | K22: B3K3G1 | N22: 42583
M23: =SUM(M20:M22) -> 0
D25: Total | G25: =SUM(G4:G19) -> 525559 | H25: =SUM(H4:H19) -> 536746 | I25: 504894 | M25: =M9+M17 -> 122500 | Z25: 1155
Q26: 900 | Z26: 80.13
D27: Potential Balance | G27: =G25 -> 525559 | H27: 584474 | I27: =G25-H25 -> -11187 | K27: 77 | AA27: =Z26*Z25 -> 92550.15
D28: Not so liquid | N28: Actual | O28: 31st Dec | P28: 31st Dec | Q28: 31st Dec | R28: 31st Dec | S28: 31st Dec | T28: 31st Dec | Z28: 1.5 | AA28: =AA27/Z28 -> 61700.1
D29: Aston | E29: Sold | G29: 0 | O29: 2015 | P29: 2016 | Q29: 2017 | R29: 2018 | S29: 2019 | T29: 2020 | U29: =T29+1 -> 2021
D30: Golf R | G30: 15000 | N30: Value | O30: 164433.05 | P30: 248589.4 | Q30: 314989.19 | R30: 335945 | S30: 336562 | T30: 374989.19
D31: Motor Bike | G31: 2000 | O31: 0 | P31: 0 | S31: 30000 | T31: 7000
G32: =SUM(G29:G31) -> 17000 | N32: Santandar | O32: 29028
N33: Total | O33: 193461.05 | P33: 248589.4 | Q33: 314989.19 | R33: 335945 | S33: 374989.19 | T33: 381989.19
D34: Less CC Debit | G34: 1600 | P34: 55128.35 | Q34: 66399.786 | R34: =R33-Q33 -> 20955.812
D36: Sub Total | G36: =G27+G32-G34 -> 540959 | N36: Q1 | P36: 282432.89 | Q36: 33843.485 | R36: 8687 | S36: 120736 | Z36: phil | AA36: 1500
N37: Q2 | P37: 294892.7 | Q37: 12459.809 | R37: 5697 | S37: 43735
D38: Tied Assetts | G38: =M25 -> 122500 | N38: Q3 | P38: 310690.69 | Q38: 15797.999 | R38: 37050 | S38: -7000
N39: Q4 | P39: 314989.19 | Q39: 4298.4936 | R39: -31361 | S39: 11634
D40: House | G40: 360000 | Q40: 66399.786 | R40: =SUM(R36:R39) -> 20073 | S40: =SUM(S36:S39) -> 169105
D41: less mortgage | G41: =G40 -> 360000
N42: Budget | O42: 31st Dec | P42: 31st Dec | Q42: 31st Dec | R42: 31st Dec | S42: 31st Dec | T42: 31st Dec | Z42: RN Pension
...

Sheet 28-02-21
A1: 201
D2: Liquid Assests | G2: Read This | J2: Tied Assests
D3: Prod | E3: Where | F3: Who | G3: 44227 | H3: 44227 | J3: Prod | K3: Where | L3: Who | M3: Amount | Q3: At Risk | R3: Not a Risk - Cash
B4: =488+743 -> 1231 | D4: ISA | E4: Ford | F4: JG | G4: 58560 | H4: 58600 | J4: Family Loans | Q4: =G25-R4 -> 366933 | R4: =SUM(G12:G16) -> 156780 | T4: 130 | V4: 102.8 | W4: Share Price
B5: =504+803 -> 1307 | D5: ISA | E5: Ford | F5: MG | G5: 58560 | H5: 58600 | J5: Faye | M5: 22000 | P5: this is 17k + 5K | T5: 71 | V5: 1.125 | W5: Exchange | AE5: NSI | AF5: 100000
D6: FundSmith | G6: 8756 | H6: 8661 | J6: Nik | M6: 5000 | N6: 155K | P6: Med | Q6: =#REF!+#REF!+G17+G18+G19 -> #REF! | T6: =T4-T5 -> 59 | AE6: Share | AF6: 85000
C7: * | D7: Hargrevaes Lansdown | G7: 1322 | H7: 1414 | J7: Les and Jon | M7: 20000 | P7: High | Q7: =SUM(G6:G10) -> 30458
C8: * | D8: Intractive Investor | G8: 18773 | H8: 18865 | J8: Phil | M8: 1500
C9: * | D9: Bakkovor Now Jarvis | G9: 468 | H9: 439 | M9: =SUM(M5:M8) -> 48500
C10: * | D10: Now CfD | G10: 1139 | H10: 1420
D11: ClearWaterCapital | G11: =58262-(G9+22137+5468) -> 30189 | H11: 23024
D12: Current account - Inv, Currt and Holid | E12: Nat West Invest/Holiday - Not EX, Not Prop, Not Current below 4K | G12: =7780-1000 -> 6780 | H12: 8000 | R12: =14514*2 -> 29028 | AE12: Invest | AF12: 40000
D13: Premium Bonds | E13: Post Office | F13: JG | G13: 50000 | H13: 50000 | AF13: =SUM(AF5:AF12) -> 225000
D14: Premium Bonds | E14: Post Office | F14: BH | J14: Rented Properties
C15: 105.06 | D15: Premium Bonds | E15: Post Office | F15: FG | G15: 50000 | H15: 50000 | J15: House | K15: 2bed | M15: 38000 | Q15: 81287
A16: Q3 | B16: Q2 | C16: 44227 | D16: Premium Bonds | E16: Post Office | F16: MG | G16: 50000 | H16: 50000 | J16: House | K16: 3bed | M16: 36000 | Q16: =#REF!*2 -> #REF!
A17: 766 | B17: 766 | C17: 774 | D17: EDSP | E17: Computershare | F17: MG | G17: 68635 | H17: 71991 | J17: Total | M17: =SUM(M15:M16) -> 74000 | N17: 73707 | Q17: =Q15-Q16 -> #REF! | X17: =SUM(A17:A19) -> 1867 | Y17: =X17*V4 -> 191927.6
A18: 504 | B18: 504 | D18: Trading Acocunt | E18: III ( both JG and MG) | F18: MGJG | G18: =21947+190+23246 -> 45383 | H18: =22892+217+24043 -> 47152
A19: 597 | B19: 555 | C19: 847 | D19: OWN SAP | F19: MG | G19: 75148 | H19: 77393
A20: 2011 | C20: 99 | D20: SAP Shares | E20: 1 free | F20: MG | J20: SAP Shares | K20: 1 free | N20: 42156 | P20: 37666 | W20: =388*70/1.43 -> 18993.007
A21: 2012 | C21: 96 | D21: SAP Shares | E21: 5 p 3y 3g | F21: MG | J21: SAP Shares | K21: 5 p 3y 3g | N21: 41791 | P21: 35143
A22: 2013 | C22: 87 | D22: SAP Shares | E22: B3K3G1 | F22: MG | J22: SAP Shares | K22: B3K3G1 | N22: 42583
M23: =SUM(M20:M22) -> 0
D25: Total | G25: =SUM(G4:G19) -> 523713 | H25: =SUM(H4:H19) -> 525559 | I25: =G25-H25 -> -1846 | M25: =M9+M17 -> 122500 | Z25: 1155
Q26: 900 | Z26: 80.13
D27: Potential Balance | K27: 77 | AA27: =Z26*Z25 -> 92550.15
D28: Not so liquid | N28: Actual | O28: 31st Dec | P28: 31st Dec | Q28: 31st Dec | R28: 31st Dec | S28: 31st Dec | T28: 31st Dec | Z28: 1.5 | AA28: =AA27/Z28 -> 61700.1
D29: Aston | E29: Sold | G29: 0 | O29: 2015 | P29: 2016 | Q29: 2017 | R29: 2018 | S29: 2019 | T29: 2020 | U29: =T29+1 -> 2021
D30: Golf R | G30: 15000 | N30: Value | O30: 164433.05 | P30: 248589.4 | Q30: 314989.19 | R30: 335945 | S30: 336562 | T30: 374989.19
D31: Motor Bike | G31: 2000 | O31: 0 | P31: 0 | S31: 30000 | T31: 7000
G32: =SUM(G29:G31) -> 17000 | N32: Santandar | O32: 29028
N33: Total | O33: 193461.05 | P33: 248589.4 | Q33: 314989.19 | R33: 335945 | S33: 374989.19 | T33: 381989.19
D34: Less CC Debit | G34: 1600 | P34: 55128.35 | Q34: 66399.786 | R34: =R33-Q33 -> 20955.812
D36: Sub Total | G36: =G27+G32-G34 -> 15400 | N36: Q1 | P36: 282432.89 | Q36: 33843.485 | R36: 8687 | S36: 120736 | Z36: phil | AA36: 1500
N37: Q2 | P37: 294892.7 | Q37: 12459.809 | R37: 5697 | S37: 43735
D38: Tied Assetts | G38: =M25 -> 122500 | N38: Q3 | P38: 310690.69 | Q38: 15797.999 | R38: 37050 | S38: -7000
N39: Q4 | P39: 314989.19 | Q39: 4298.4936 | R39: -31361 | S39: 11634
D40: House | G40: 360000 | Q40: 66399.786 | R40: =SUM(R36:R39) -> 20073 | S40: =SUM(S36:S39) -> 169105
D41: less mortgage | G41: =G40 -> 360000
N42: Budget | O42: 31st Dec | P42: 31st Dec | Q42: 31st Dec | R42: 31st Dec | S42: 31st Dec | T42: 31st Dec | Z42: RN Pension
...

Sheet 31-03-21
A1: 201
D2: Liquid Assests | G2: Read This | J2: Tied Assests
D3: Prod | E3: Where | F3: Who | G3: 44286 | H3: 44227 | J3: Prod | K3: Where | L3: Who | M3: Amount | Q3: At Risk | R3: Not a Risk - Cash
B4: =488+743 -> 1231 | D4: ISA | E4: Ford | F4: JG | G4: 58606 | H4: 58600 | J4: Family Loans | Q4: =G25-R4 -> 368569 | R4: =SUM(G12:G16) -> 171300 | T4: 130 | V4: 102.8 | W4: Share Price
B5: =504+803 -> 1307 | D5: ISA | E5: Ford | F5: MG | G5: 58606 | H5: 58600 | J5: Faye | M5: 22000 | P5: this is 17k + 5K | T5: 71 | V5: 1.125 | W5: Exchange | AE5: NSI | AF5: 100000
D6: FundSmith | G6: 8941 | H6: 8661 | J6: Nik | M6: 5000 | N6: 155K | P6: Med | Q6: =#REF!+#REF!+G17+G18+G19 -> #REF! | T6: =T4-T5 -> 59 | AE6: Share | AF6: 85000
C7: * | D7: Hargrevaes Lansdown | G7: 1309 | H7: 1414 | J7: Les and Jon | M7: 20000 | P7: High | Q7: =SUM(G6:G10) -> 31389
C8: * | D8: Intractive Investor | G8: 19029 | H8: 18865 | J8: Phil | M8: 1500
C9: * | D9: Bakkovor Now Jarvis | G9: 620 | H9: 439 | M9: =SUM(M5:M8) -> 48500
C10: * | D10: Now CfD | G10: 1490 | H10: 1420
D11: ClearWaterCapital | G11: 28000 | H11: 23024
D12: Current account - Inv, Currt and Holid | E12: Nat West Invest/Holiday - Not EX, Not Prop, Not Current below 4K | G12: 21300 | H12: 8000 | R12: =14514*2 -> 29028 | AE12: Invest | AF12: 40000
D13: Premium Bonds | E13: Post Office | F13: JG | G13: 50000 | H13: 50000 | AF13: =SUM(AF5:AF12) -> 225000
D14: Premium Bonds | E14: Post Office | F14: BH | J14: Rented Properties
C15: 105.06 | D15: Premium Bonds | E15: Post Office | F15: FG | G15: 50000 | H15: 50000 | J15: House | K15: 2bed | M15: 38000 | Q15: 81287
A16: Q3 | B16: Q2 | C16: 44227 | D16: Premium Bonds | E16: Post Office | F16: MG | G16: 50000 | H16: 50000 | J16: House | K16: 3bed | M16: 36000 | Q16: =#REF!*2 -> #REF!
A17: 766 | B17: 766 | C17: 774 | D17: EDSP | E17: equateplus.com | F17: MG | G17: 68883 | H17: 71991 | J17: Total | M17: =SUM(M15:M16) -> 74000 | N17: 73707 | Q17: =Q15-Q16 -> #REF! | X17: =SUM(A17:A19) -> 1867 | Y17: =X17*V4 -> 191927.6
A18: 504 | B18: 504 | D18: Trading Account | E18: III ( both JG and MG) | F18: MGJG | G18: =23501+22680 -> 46181 | H18: =22892+217+24043 -> 47152
A19: 597 | B19: 555 | C19: 864.54 | D19: OWN SAP | E19: equateplus.com | F19: MG | G19: 76904 | H19: 77393
A20: 2011 | C20: 99 | D20: SAP Shares | E20: 1 free | F20: MG | J20: SAP Shares | K20: 1 free | N20: 42156 | P20: 37666 | W20: =388*70/1.43 -> 18993.007
A21: 2012 | C21: 96 | D21: SAP Shares | E21: 5 p 3y 3g | F21: MG | J21: SAP Shares | K21: 5 p 3y 3g | N21: 41791 | P21: 35143
A22: 2013 | C22: 87 | D22: SAP Shares | E22: B3K3G1 | F22: MG | J22: SAP Shares | K22: B3K3G1 | N22: 42583
M23: =SUM(M20:M22) -> 0
D25: Total | G25: =SUM(G4:G19) -> 539869 | H25: =SUM(H4:H19) -> 525559 | I25: =G25-H25 -> 14310 | M25: =M9+M17 -> 122500 | Z25: 1155
Q26: 900 | Z26: 80.13
D27: Potential Balance | K27: 77 | AA27: =Z26*Z25 -> 92550.15
D28: Not so liquid | N28: Actual | O28: 31st Dec | P28: 31st Dec | Q28: 31st Dec | R28: 31st Dec | S28: 31st Dec | T28: 31st Dec | Z28: 1.5 | AA28: =AA27/Z28 -> 61700.1
D29: Aston | E29: Sold | G29: 0 | O29: 2015 | P29: 2016 | Q29: 2017 | R29: 2018 | S29: 2019 | T29: 2020 | U29: =T29+1 -> 2021
D30: Golf R | G30: 15000 | N30: Value | O30: 164433.05 | P30: 248589.4 | Q30: 314989.19 | R30: 335945 | S30: 336562 | T30: 374989.19
D31: Motor Bike | G31: 2000 | O31: 0 | P31: 0 | S31: 30000 | T31: 7000
G32: =SUM(G29:G31) -> 17000 | N32: Santandar | O32: 29028
N33: Total | O33: 193461.05 | P33: 248589.4 | Q33: 314989.19 | R33: 335945 | S33: 374989.19 | T33: 381989.19
D34: Less CC Debit | G34: 1600 | P34: 55128.35 | Q34: 66399.786 | R34: =R33-Q33 -> 20955.812
D36: Sub Total | G36: =G27+G32-G34 -> 15400 | N36: Q1 | P36: 282432.89 | Q36: 33843.485 | R36: 8687 | S36: 120736 | Z36: phil | AA36: 1500
N37: Q2 | P37: 294892.7 | Q37: 12459.809 | R37: 5697 | S37: 43735
D38: Tied Assetts | G38: =M25 -> 122500 | N38: Q3 | P38: 310690.69 | Q38: 15797.999 | R38: 37050 | S38: -7000
N39: Q4 | P39: 314989.19 | Q39: 4298.4936 | R39: -31361 | S39: 11634
D40: House | G40: 360000 | Q40: 66399.786 | R40: =SUM(R36:R39) -> 20073 | S40: =SUM(S36:S39) -> 169105
D41: less mortgage | G41: =G40 -> 360000
N42: Budget | O42: 31st Dec | P42: 31st Dec | Q42: 31st Dec | R42: 31st Dec | S42: 31st Dec | T42: 31st Dec | Z42: RN Pension
...

Sheet 30-04-21
A1: 201
D2: Liquid Assests | G2: Read This | J2: Tied Assests
D3: Prod | E3: Where | F3: Who | G3: 44347 | H3: 44316 | J3: Prod | K3: Where | L3: Who | M3: Amount | Q3: At Risk | R3: Not a Risk - Cash
B4: =488+743 -> 1231 | D4: ISA | E4: Ford | F4: JG | G4: 60898 | H4: 61166 | J4: Family Loans | Q4: =G25-R4 -> 398026 | R4: =SUM(G12:G16) -> 157000 | T4: 130 | V4: 102.8 | W4: Share Price
B5: =504+803 -> 1307 | D5: ISA | E5: Ford | F5: MG | G5: 60898 | H5: 61166 | J5: Faye | M5: 22000 | P5: this is 17k + 5K | T5: 71 | V5: 1.125 | W5: Exchange | AE5: NSI | AF5: 100000
D6: FundSmith | G6: 9400 | H6: 9495 | J6: Nik | M6: 5000 | N6: 155K | P6: Med | Q6: =#REF!+#REF!+G17+G18+G19 -> #REF! | T6: =T4-T5 -> 59 | AE6: Share | AF6: 85000
C7: * | D7: Hargrevaes Lansdown | G7: 1223 | H7: 1266 | J7: Les and Jon | M7: 20000 | P7: High | Q7: =SUM(G6:G10) -> 31234
C8: * | D8: Intractive Investor | G8: 18643 | H8: 19165 | J8: Phil | M8: 1500
C9: * | D9: Bakkovor Now Jarvis | G9: 718 | H9: 698 | M9: =SUM(M5:M8) -> 48500
C10: * | D10: Now CfD | G10: 1250 | H10: 1403 | J10: Cars
D11: ClearWaterCapital | G11: 28000 | H11: 28000 | J11: MG | M11: 9000
D12: Current account - Inv, Currt and Holid | E12: Nat West Invest/Holiday - Not EX, Not Prop, Not Current below 4K | G12: 7000 | H12: 9000 | J12: Yeti | M12: 11000 | R12: =14514*2 -> 29028 | AE12: Invest | AF12: 40000
D13: Premium Bonds | E13: Post Office | F13: JG | G13: 50000 | H13: 50000 | M13: =SUM(M11:M12) -> 20000 | AF13: =SUM(AF5:AF12) -> 225000
D14: Premium Bonds | E14: Post Office | F14: BH | J14: Rented Properties
C15: 105.06 | D15: Premium Bonds | E15: Post Office | F15: FG | G15: 50000 | H15: 50000 | J15: House | K15: 2bed | M15: =38000+1500 -> 39500 | Q15: 81287
A16: Q3 | B16: Q2 | C16: 44227 | D16: Premium Bonds | E16: Post Office | F16: MG | G16: 50000 | H16: 50000 | J16: House | K16: 3bed | M16: =38000+1500 -> 39500 | Q16: =#REF!*2 -> #REF!
A17: 766 | B17: 766 | C17: 774 | D17: EDSP | E17: equateplus.com | F17: MG | G17: 76583 | H17: 78758 | J17: Total | M17: =SUM(M15:M16) -> 79000 | N17: 73707 | Q17: =Q15-Q16 -> #REF! | X17: =SUM(A17:A19) -> 1867 | Y17: =X17*V4 -> 191927.6
A18: 504 | B18: 504 | D18: Trading Account | E18: III ( both JG and MG) | F18: MGJG | G18: =26323+25555 -> 51878 | H18: =26323+25555 -> 51878
A19: 597 | B19: 555 | C19: 880 | D19: OWN SAP | E19: equateplus.com | F19: MG | G19: 88535 | H19: 89536
A20: 2011 | C20: 99 | D20: SAP Shares | E20: 1 free | F20: MG | J20: SAP Shares | K20: 1 free | N20: 42156 | P20: 37666 | W20: =388*70/1.43 -> 18993.007
A21: 2012 | C21: 96 | D21: SAP Shares | E21: 5 p 3y 3g | F21: MG | J21: SAP Shares | K21: 5 p 3y 3g | N21: 41791 | P21: 35143
A22: 2013 | C22: 87 | D22: SAP Shares | E22: B3K3G1 | F22: MG | J22: SAP Shares | K22: B3K3G1 | N22: 42583
M23: =SUM(M20:M22) -> 0
D25: Total | G25: =SUM(G4:G19) -> 555026 | H25: =SUM(H4:H19) -> 561531 | I25: =G25-H25 -> -6505 | M25: =M9+M17+M13 -> 147500 | Z25: 1155
Q26: 900 | Z26: 80.13
D27: Potential Balance | K27: 77 | AA27: =Z26*Z25 -> 92550.15
D28: Not so liquid | N28: Actual | O28: 31st Dec | P28: 31st Dec | Q28: 31st Dec | R28: 31st Dec | S28: 31st Dec | T28: 31st Dec | Z28: 1.5 | AA28: =AA27/Z28 -> 61700.1
D29: Aston | E29: Sold | G29: 0 | O29: 2015 | P29: 2016 | Q29: 2017 | R29: 2018 | S29: 2019 | T29: 2020 | U29: =T29+1 -> 2021
D30: Golf R | G30: 15000 | N30: Value | O30: 164433.05 | P30: 248589.4 | Q30: 314989.19 | R30: 335945 | S30: 336562 | T30: 374989.19
D31: Motor Bike | G31: 2000 | O31: 0 | P31: 0 | S31: 30000 | T31: 7000
G32: =SUM(G29:G31) -> 17000 | N32: Santandar | O32: 29028
N33: Total | O33: 193461.05 | P33: 248589.4 | Q33: 314989.19 | R33: 335945 | S33: 374989.19 | T33: 381989.19
D34: Less CC Debit | G34: 1600 | P34: 55128.35 | Q34: 66399.786 | R34: =R33-Q33 -> 20955.812
D36: Sub Total | G36: =G27+G32-G34 -> 15400 | N36: Q1 | P36: 282432.89 | Q36: 33843.485 | R36: 8687 | S36: 120736 | Z36: phil | AA36: 1500
N37: Q2 | P37: 294892.7 | Q37: 12459.809 | R37: 5697 | S37: 43735
D38: Tied Assetts | G38: =M25 -> 147500 | N38: Q3 | P38: 310690.69 | Q38: 15797.999 | R38: 37050 | S38: -7000
N39: Q4 | P39: 314989.19 | Q39: 4298.4936 | R39: -31361 | S39: 11634
D40: House | G40: 360000 | Q40: 66399.786 | R40: =SUM(R36:R39) -> 20073 | S40: =SUM(S36:S39) -> 169105
D41: less mortgage | G41: =G40 -> 360000
N42: Budget | O42: 31st Dec | P42: 31st Dec | Q42: 31st Dec | R42: 31st Dec | S42: 31st Dec | T42: 31st Dec | Z42: RN Pension
...

Sheet 30-06-21
A1: 201
D2: Liquid Assests | G2: Read This | J2: Tied Assests
D3: Prod | E3: Where | F3: Who | G3: 44377 | H3: 44347 | J3: Prod | K3: Where | L3: Who | M3: Amount | Q3: At Risk | R3: Not a Risk - Cash
B4: =488+743 -> 1231 | D4: ISA | E4: Ford | F4: JG | G4: =37676+24892 -> 62568 | H4: 60898 | J4: Family Loans | Q4: =G25-R4 -> 411777 | R4: =SUM(G12:G16) -> 156000 | T4: 130 | V4: 102.8 | W4: Share Price
B5: =504+803 -> 1307 | D5: ISA | E5: Ford | F5: MG | G5: =37676+24892 -> 62568 | H5: 60898 | J5: Faye | M5: 22000 | P5: this is 17k + 5K | T5: 71 | V5: 1.125 | W5: Exchange | AE5: NSI | AF5: 100000
D6: FundSmith | G6: 10021 | H6: 9400 | J6: Nik | M6: 5000 | N6: 155K | P6: Med | Q6: =#REF!+#REF!+G17+G18+G19 -> #REF! | T6: =T4-T5 -> 59 | AE6: Share | AF6: 85000
C7: * | D7: Hargrevaes Lansdown | G7: 1329 | H7: 1223 | J7: Les and Jon | M7: 20000 | P7: High | Q7: =SUM(G6:G10) -> 21990
C8: * | D8: Intractive Investor | G8: 8961 | H8: 18643 | J8: Phil | M8: 1500
C9: * | D9: Bakkovor Now Jarvis | G9: 679 | H9: 718 | M9: =SUM(M5:M8) -> 48500
C10: * | D10: Now CfD | G10: 1000 | H10: 1250 | J10: Cars
D11: ClearWaterCapital | G11: =28000+10252 -> 38252 | H11: 28000 | J11: MG | M11: 9000
D12: Current account - Inv, Currt and Holid | E12: Nat West Invest/Holiday - Not EX, Not Prop, Not Current below 4K | G12: 6000 | H12: 7000 | J12: Yeti | M12: 11000 | R12: =14514*2 -> 29028 | AE12: Invest | AF12: 40000
D13: Premium Bonds | E13: Post Office | F13: JG | G13: 50000 | H13: 50000 | M13: =SUM(M11:M12) -> 20000 | AF13: =SUM(AF5:AF12) -> 225000
D14: Premium Bonds | E14: Post Office | F14: BH | J14: Rented Properties
C15: 105.06 | D15: Premium Bonds | E15: Post Office | F15: FG | G15: 50000 | H15: 50000 | J15: House | K15: 2bed | M15: =38000+1500 -> 39500 | Q15: 81287
A16: Q3 | B16: Q2 | C16: 44227 | D16: Premium Bonds | E16: Post Office | F16: MG | G16: 50000 | H16: 50000 | J16: House | K16: 3bed | M16: =38000+1500 -> 39500 | Q16: =#REF!*2 -> #REF!
